Workbook
Name a: #REF!
Name a: #REF!
Name a: #REF!
Name PotInv: Input!$I$36
Name PotMod: Input!$C$39
Name TelFixo: Input!$C$9
Name TelMovel: Input!$C$10

Sheet Input
B2: N° TRT | E2: Padrão de Entrada (categoria RIC BT ou GED-13): | F2: A2 (Conforme anexo J - RIC BT)
B3: Data | C3: 12/05/2026 | E3: Tipo de Cabos | F3: Cobre
B4: NÚMERO UNIDADE CONSUMIDORA | C4: 3090243410 | E4: Tipo de Atendimento | F4: Aéreo
B5: NOME CLIENTE / REQUERENTE | C5: ANA MARIA CARDOZO DOS SANTOS | E5: Número de Fases da Instalação | F5: Monofásico | G5: =IF(F5="Trifásico",4,IF(F5="Bifásico",3,IF(F5="Monofásico",2,""))) -> 2 | H5: =IF(F3="alumínio","T-","")
B6: TIPO CLIENTE | C6: CPF | E6: Cabos (seção transversal em mm²): | F6: 10 | K6: =IF(F2="","",VLOOKUP($F$2,Valid.Dados!$C$23:$H$119,4,FALSE)) -> 6 | L6: =IF(F2="","",VLOOKUP($F$2,Valid.Dados!$C$23:$H$119,5,FALSE)) -> 10
B7: CPF/CNPJ | C7: 404.289.070-91 | E7: CAIXA DE MEDIÇÃO
B8: EMAIL | C8: batistajbs@gmail.com | E8: Material | F8: Policarbonato
B9: TEL. FIXO (CLIENTE / REQUERENTE) | C9: +55 51 98457-2961 | E9: Tamanho | F9: Monofásica
B10: TEL. CEL (CLIENTE / REQUERENTE) | C10: +55 51 98457-2961 | E10: Tipo | F10: CE
B11: Se for um CNPJ: | E11: Caixa de Medição (segundo GED 14945): | F11: =IF(F8="padrão multi 100",F8,IF(F8="padrão multi 200",F8,IF(F8="","",CONCATENATE(F10," - Tamanho ",F9,", ",F8," (conforme RIC BT)")))) -> CE - Tamanho Monofásica, Policarbonato (conforme RIC BT)
B12: CPF DO RESPONSÁVEL | C12: =IF($C$6="CNPJ","?","--") -> --
B13: NOME DO RESPONSÁVEL | C13: =IF($C$6="CNPJ","?","--") -> -- | E13: GRUPO | F13: Grupo B | G13: Se A, medido em B, => B
B14: FUNÇÃO/CARGO DO RESPONSÁVEL | C14: =IF($C$6="CNPJ","?","--") -> -- | E14: SUBGRUPO | F14: B1 - Residencial
E15: CLASSE | F15: Residencial
B16: Dados Requerente é igual ao da Obra? | C16: Sim | E16: Tipo de Sistema Fotovoltaico | F16: =IF(G25>75,"minigeração","microgeração") -> microgeração | G16: DEMANDA CONTRATADA (kW) | H16: =IF(F16=Valid.Dados!A31,"?","--") -> --
B17: REQUERENTE | E17: TENSÃO DE ATENDIMENTO | F17: =IF(F16=Valid.Dados!A31,"?","--") -> -- | G17: Potência Nominal Transformador | H17: =IF(F16=Valid.Dados!A31,"?","--") -> --
E18: Tipo de ligação do transformador | F18: =IF(F16=Valid.Dados!A31,"?","--") -> -- | G18: Qtd (motores Potência ≤ 75 CV) | H18: =IF(F16=Valid.Dados!A31,"?","--") -> --
B19: RUA / AVENIDA / ESTRADA | C19: Rua | E19: Impedância percentual do transformador: | F19: =IF(F16=Valid.Dados!A31,"?","--") -> -- | G19: Qtd (motores Potência > 75 CV) | H19: =IF(F16=Valid.Dados!A31,"?","--") -> --
B20: LOGRADOURO | C20: RIO GRANDE | E20: TENSÃO DE ATENDIMENTO (se média tensão) | F20: =IF(F16=Valid.Dados!A31,"?","--") -> --
B21: NÚMERO | C21: 12 | E21: TENSÃO DE CONEXÃO | F21: 220/380
B22: BAIRRO | C22: SCHARLAU | E22: TIPO DE LIGAÇÃO | F22: Comum trifásica BT | G22: kVA
B23: MUNICIPIO | C23: SÃO LEOPOLDO | E23: TIPO DE ATIVIDADE *** | F23: Residencial | G23: kW
B24: CEP | C24: 93135-673 | E24: Dem.Disponib. (se MT) ou Carga Instalada (se BT): | F24: =IF($F$2="","",VLOOKUP($F$2,Valid.Dados!$C$23:$E643,2,FALSE)) -> 15 | G24: POTENCIA DO SISTEMA
B25: OBRA | E25: Disjuntor (A): | F25: =IF($F$2="","",VLOOKUP($F$2,Valid.Dados!$C$23:$E$63,3,FALSE)) -> 40 | G25: =IF(I36="",0,IF(PotMod>PotInv,PotInv,PotMod)) -> 6
B26: RUA / AVENIDA / ESTRADA | C26: =IF($C$16="Sim",C19,"?") -> Rua | E26: CARGA INSTALADA | F26: =IF($F$2="","",VLOOKUP($F$2,Valid.Dados!$C$23:$E643,2,FALSE)) -> 15
B27: LOGRADOURO | C27: =IF($C$16="Sim",C20,"?") -> RIO GRANDE
B28: NÚMERO | C28: =IF($C$16="Sim",C21,"?") -> 12 | F28: INVERSOR MODELO #1 | G28: INVERSOR MODELO #2 | I28: TOTAIS
B29: BAIRRO | C29: =IF($C$16="Sim",C22,"?") -> SCHARLAU | E29: QUANTIDADE | F29: 1 | I29: =SUM(F29:H29) -> 1
B30: MUNICIPIO | C30: =IF($C$16="Sim",C23,"?") -> SÃO LEOPOLDO | E30: FABRICANTE | F30: Goodwe | I30: --
B31: CEP | C31: =IF($C$16="Sim",C24,"?") -> 93135-673 | E31: MODELO | F31: GW6K-DNS-G40 | I31: --
B32: LATITUDE | C32: -29.717802823738648 | E32: POTÊNCIA TOTAL (CC) | F32: 6 | G32: =IF(G31="","",VLOOKUP(G31,'BD Inv'!$A$3:$AN$624,'BD Inv'!$J$1,FALSE)/1000*G29) | I32: =SUM(F32:H32) -> 6
B33: LONGITUDE | C33: -51.166825400341295 | E33: CERTIFICADO INMETRO | F33: 0 | G33: =IF(G31="","",VLOOKUP(G31,'BD Inv'!$A$3:$AN$624,'BD Inv'!$P$1,FALSE)) | I33: --
E34: POTÊNCIA NOMINAL UNITÁRIO | F34: 6 | G34: =IF(G31="",0,VLOOKUP(G31,'BD Inv'!$A$3:$AN$624,'BD Inv'!$J$1,FALSE)/1000) -> 0 | I34: =SUM(F34:H34) -> 6
B35: MÓDULOS | E35: POTÊNCIA NOMINAL TOTAL | F35: 6 | G35: =IF(G29="",0,G34*G29) -> 0 | I35: =SUM(F35:H35) -> 6
B36: QUANTIDADE | C36: 12 | I36: =IF(F29="","",IF(G29="",F29*F34,F34*F29+G34*G29)) -> 6 | M36: Ainda refinar como incluir esses dados
B37: FABRICANTE | C37: Pulling Energy | E37: TIPO DE OBRA** | F37: =F16 -> microgeração | G37: kW | M37: no memorial
B38: MODELO | C38: PU585WNM101 | E38: Tipo de ligação do transformador (se mini) | F38: =IF($F$37="Minigeração distribuída","","--") -> --
B39: POTÊNCIA TOTAL (kW) | C39: =IF($C$38="",0,C36*C41/1000) -> 7.02 | E39: Impedância percentual do transf. (se mini) | F39: =IF($F$37="Minigeração distribuída","","--") -> --
B40: ÁREA TOTAL (m²) | C40: =IF($C$38="","",C36*C44) -> 31.752907
B41: POTÊNCIA | C41: =IF($C$38="","",VLOOKUP($C$38,'BD Mod'!$B$2:$AG$186,'BD Mod'!$D$1,FALSE)) -> 585
...

Sheet Ordem de Serviço
C4: Ordem de Serviço
C6: 1 - Informações do Cliente
C7: Cliente | E7: =+Input!C5 -> ANA MARIA CARDOZO DOS SANTOS
C8: Rua/Av.: | E8: =+Input!C20 -> RIO GRANDE | L8: N°: | N8: =Input!C21 -> 12
C9: Bairro: | E9: =+Input!C22 -> SCHARLAU | L9: Cidade: | N9: =Input!C23 -> SÃO LEOPOLDO
C10: Celular | E10: =+Input!C10 -> +55 51 98457-2961
C12: 2 - Informações do Sistema
C13: Inversor: | E13: =Input!F30 -> Goodwe | K13: Modelo: | M13: =Input!F31 -> GW6K-DNS-G40 | Q13: MPPT: | R13: 2
C14: Disjuntor: | E14: 1 X Monofásico 32A | K14: Cabo : | M14: 4 mm² | Q14: DPS: | R14: 2 X Classe II 20kA | U14: kWp limitado em kW
C15: Módulos: | E15: =Input!C37 -> Pulling Energy | K15: Modelo: | M15: =Input!C38 -> PU585WNM101 | Q15: Potência: | R15: =CONCATENATE(Input!C41," Wp") -> 585 Wp
C16: Quantidade total de módulos: | I16: =Input!C36 -> 12 | K16: Strings: | M16: 2 | O16: String 1: | R16: 6
C17: Potência do Sistema: | I17: =CONCATENATE(Input!C39," kWp") -> 7,02 kWp | O17: String 2: | R17: 6
C19: 3 - Informações Sobre a Instalação
C20: Estrutura: | F20: Fibrocimento | M20: Posição Solar: | Q20: Norte / Leste
C21: Informações sobre a Instalação:
C24: Fachada da Residência: | O24: Telhado para Instalação:
C37: Local | K37: Data | N37: Responsáveis pela execução da obra

Sheet Lista de materiais
C4: Checklist de Materiais
C6: 1 - Informações do Cliente
C7: Clinete: | E7: =+Input!C5 -> ANA MARIA CARDOZO DOS SANTOS
C8: Rua/Av.: | E8: =+Input!C20 -> RIO GRANDE | L8: N°: | N8: =Input!C21 -> 12
C9: Bairro: | E9: =+Input!C22 -> SCHARLAU | L9: Cidade: | N9: =Input!C23 -> SÃO LEOPOLDO
C11: 2 - Checklist de Materiais
C12: ITEM | D12: DESCRIÇÃO | M12: Característica - Qtd. | R12: Unid.
C13: Proteção
C14: 1 | D14: Quadro de distribuição de sobr. 4P( ) ou 8 P( ) | R14: Pç
C15: 2 | D15: Disjuntor CA -16( ) 20( ) 25( ) 32( ) 40( ) 50( ) | R15: Pç
C16: 3 | D16: DPS CA, Classe 2, 15 kA | R16: Pç
C17: 4 | D17: Conector MC4 (macho + fêmea) | R17: Pç
C18: Eletrovias / fixação / sinalização
C19: 1 | D19: Eletroduto rígido de PVC S/R BR | R19: Pç
C20: 2 | D20: Luva rígida de PVC S/R rosca BR | R20: Pç
C21: 3 | D21: Abraçadeira de PVC rígida BR | R21: Pç
C22: 4 | D22: Condulete rígido de PVC BR | R22: Pç
C23: 5 | D23: Adaptador p/ condulete de PVC BR | R23: Pç
C24: 6 | D24: Tampa cega p/ condulete de PVC BR | R24: Pç
C25: 7 | D25: Tampão p/ conduletede de PVC BR | R25: Pç
C26: 8 | D26: Eletroduto flexível de PVC | R26: Pç
C27: 9 | D27: Selante PU | R27: Pç
C28: 10 | D28: Manta asfáltica | R28: m
C29: 11 | D29: Cinta perfurada | R29: m
C30: 12 | D30: Placas de advertência | R30: Pç
C31: 13 | D31: Espiral branco 1/2" | R31: m
C32: Cabos
C33: 1 | D33: Cabo flexível classe 5 de PVC 4,0mm² | R33: m
C34: 2 | D34: Cabo flexível classe 5 de PVC 4,0mm² | R34: m
C35: 3 | D35: Cabo flexível classe 5 de PVC 4,0mm² | R35: m
C36: 4 | D36: Cabo flexível classe 5 de PVC 6,0mm² | R36: m
C37: 5 | D37: Cabo flexível classe 5 de PVC 6,0mm² | R37: m
C38: 6 | D38: Cabo flexível classe 5 de PVC 6,0mm² | R38: m
C39: Observações:
C43: =N9 -> SÃO LEOPOLDO
C44: Local | J44: Data | N44: Técnico Responsável

Sheet AN. F (NOVO)
B2: ANEXO F – Dados para Registro de Micro e Minigeradores Distribuídos Participantes do Sistema de Compensação de Energia Elétrica
B4: Na ocasião da Solicitação de Acesso, as informações pedidas para este Anexo F são mandatórias e serão remetidas pela CPFL à ANEEL, conforme por esta própria determinado, após a liberação da conexão. O acessante deverá estar ciente de que a citada liberação também depende do correto preenchimento do que aqui se solicita. Este refere-se a cada unidade consumidora que tiver aprovada central de micro ou minigeração distribuída aderente ao sistema de compensação de energia elétrica e deverá ser preenchida pelo acessante (deixar em branco o que não se aplicar).
B6: Na ocasião da Consulta de Acesso é incentivado que o acessante envie este anexo preenchido, em especial os itens marcados com asterisco. Somente com as informações destes itens será possível avaliar a viabilidade e estimar as obras em virtude da conexão de minigeradores. Sem eles, a Informação de Acesso da CPFL conterá apenas os dados elétricos da região em que pretende-se conexão.
B8: 1) Dados da Unidade Consumidora (UC):
B9: 1.1) Nome do titular: * | H9: =+Input!C5 -> ANA MARIA CARDOZO DOS SANTOS
B10: 1.2) CNPJ ou CPF (titular): * | H10: =+Input!C7 -> 404.289.070-91
B11: 1.3) Número da UC (se existente) * | H11: =Input!C4 -> 3090243410
B12: 1.4) Endereço do titular | H12: =CONCATENATE(Input!C19,", ",Input!C20," ",Input!C21,", ",Input!C22) -> Rua, RIO GRANDE 12, SCHARLAU
B13: 1.5) CEP do titular | H13: =Input!C24 -> 93135-673
B14: 1.6) Município do titular | H14: =+CONCATENATE(Input!C23," / RS") -> SÃO LEOPOLDO / RS
B15: 1.7) Latitude (SIRGAS 2000) | H15: =Input!C32 -> -29.717802823738648
B16: 1.8) Longitude (SIRGAS 2000) | H16: =Input!C33 -> -51.166825400341295
B17: 1.9) Telefone do titular: | H17: =IF(TelFixo="--",TelMovel,IF(TelMovel="--",TelFixo,CONCATENATE(TelFixo," / ",TelMovel))) -> +55 51 98457-2961 / +55 51 98457-2961
B18: 1.10) E-mail do titular: | H18: =Input!C8 -> batistajbs@gmail.com
B19: 1.11) Usina foi objeto de Outorga ou Registro? | H19: ☐Sim ☒Não Se sim, preencher os campos abaixo
B20: 1.12) CEG | H20: -
B21: 1.13) Número do Ato de Outorga ou Registro | H21: -
B22: 1.14) Ano do Ato de Outorga ou Registro | H22: -
B23: 2a) Dados Técnicos da Unidade Consumidora (se Microgeração) | H23: Existente | L23: Novo
B24: 2.1) Padrão de Entrada (categoria - GED 13/RIC BT): | H24: =IF(Input!$F$16="minigeração","--",+Input!F2) -> A2 (Conforme anexo J - RIC BT)
B25: 2.2) Tipo de Atendimento (aéreo/subterrâneo): | H25: =IF(Input!$F$16="minigeração","--",Input!F4) -> Aéreo
B26: 2.3) Número de Fases da Instalação (Monofásico/Bifásico/Trifásico): | H26: =IF(Input!$F$16="minigeração","--",Input!F5) -> Monofásico
B27: 2.4) Cabos (seção transversal): | H27: =IF(Input!$F$16="minigeração","--",Input!F6) -> 10
B28: 2.5) Caixa de Medição (tipo, segundo GED 14945): | H28: =IF(Input!$F$16="minigeração","--",Input!F11) -> CE - Tamanho Monofásica, Policarbonato (conforme RIC BT)
B29: 2.6) Demanda Disponibilizada (se MT) ou Carga Instalada (se BT): | H29: =IF(Input!$F$16="minigeração","--",Input!F24) -> 15
B30: 2.7) Disjuntor (A): | H30: =IF(Input!$F$16="minigeração","--",Input!F25) -> 40
B31: 2b) Dados Técnicos da Unidade Consumidora (se Minigeração) | H31: Existente | K31: Acréscimo | N31: Total
B32: 2.1) Carga instalada (kW): * | H32: =IF(Input!$F$16<>"minigeração","--",Input!F26) -> --
B33: 2.2) Demanda contratada (kW): * | H33: =IF(Input!$F$16<>"minigeração","--",Input!H16) -> --
B34: 2.3) Quantidade de motores com potência acima de 75 CV: *¹ | H34: =IF(Input!$F$16<>"minigeração","--",Input!H19) -> --
B35: 2.4) Quantidade de motores com potência menor ou igual a 75 CV: * | H35: =IF(Input!$F$16<>"minigeração","--",Input!H18) -> --
B36: 2.5) Potência instalada de geração (kVA): * | H36: =IF(Input!$F$16="minigeração",Input!C39,"--") -> --
B37: 2.6) Potência exportada de geração (kW): * | H37: =H36 -> --
B38: 2.7) Nome do responsável técnico: * | H38: Tiago Vicente Flores
B39: 2.8) Número do registro (CREA) do responsável técnico: * | H39: 83678794068
B40: 2.9) Número do telefone do responsável técnico: | H40: =H37 -> --
B41: 2.10) Data pretendida para entrada em operação (dd/mm/aaaa):
B42: 2c) Dados dos transformadores de acoplamento (se Minigeração) | H42: T1 | J42: T2 | L42: T3 | N42: T4
B43: 2.1) Potência Nominal (kVA): * | H43: =IF(Input!$F$16<>"minigeração","--",Input!H17) -> --
B44: 2.2) Tensão Primária (kV): * | H44: =IF(Input!$F$16<>"minigeração","--",Input!F20) -> --
...

Sheet Valid.Dados
A1: COMPARTILHAMENTO DE CRÉDITOS | C1: SUBGRUPO | E1: CLASSE | H1: TENSÃO DE CONEXÃO | J1: CLASSIFICAÇÃO USINA | L1: EIXO DO ROTOR | N1: FONTE | P1: MÁQUINA MOTRIZ | R1: CICLO TERMODINÂMICO | T1: 2.2) Tipo de Atendimento (aéreo/subterrâneo): | V1: 2.3) Número de Fases da Instalação (Monofásico/Bifásico/Trifásico): | X1: 1.4) Grupo (A – alta tensão, ou B – baixa tensão; caso a UC seja Grupo A, mas faturada como B, informar B): | Z1: Compartilhamento Crédito | AD1: Módulos | AF1: Inversor | AH1: CABEAMENTO CC | AN1: CABEAMENTO CA
A2: Sem compartilhamento | C2: A1 - Tensão de fornecimento igual ou superior a 230 kV | E2: Residencial | H2: 127 | J2: CGH - Central Geradora Hidrelétrica | L2: Vertical | N2: UTE - Biomassa - Bagaço de Cana-de-Açucar | P2: Motor | R2: Aberto | T2: Aéreo | V2: Trifásico | X2: Grupo A | Z2: -- | AB2: Alumínio | AD2: ZN Shine | AF2: Fronius | AL2: não | AR2: não
A3: Autoconsumo Remoto | C3: A2 - Tensão de fornecimento de 88 kV a 138 kV | E3: Comercial | H3: 220 | J3: EOL - Usina Eólica | L3: Horizontal | N3: UTE - Biomassa - Biogás - Floresta | P3: Turbina | R3: Fechado | T3: Subterrâneo | V3: Bifásico | X3: Grupo B | Z3: 1 | AB3: Cobre | AD3: BYD | AF3: ABB | AH3: =CONCATENATE("Até ",AI3, "mm2") -> Até 4mm2 | AI3: 4 | AJ3: =+IF(AL3="Sim",IF(AL2="Não","Sim","Não"),"Não") -> #DIV/0! | AK3: 6 | AL3: =+IF(Input!$F$49<AI3,"Sim","Não") -> #DIV/0! | AN3: =CONCATENATE("Até ",AO3, "mm2") -> Até 2,5mm2 | AO3: 2.5 | AP3: =+IF(AR3="Sim",IF(AR2="Não","Sim","Não"),"Não") -> Sim | AQ3: 2.5 | AR3: =+IF(Input!$I$48<AO3,"Sim","Não") -> Sim
A4: Geração Compartilhada | C4: A3 - Tensão de fornecimento de 69 kV | E4: Rural | H4: 127/220 | J4: UFV - Usina Fotovoltáica | N4: UTE - Biomassa - Biogás - RA | V4: Monofásico | Z4: 2 | AD4: Canadian | AF4: Canadian | AH4: =CONCATENATE("De ",AI3," até ",AI4," mm2") -> De 4 até 6 mm2 | AI4: 6 | AJ4: =+IF(AL4="Sim",IF(AL3="Não","Sim","Não"),"Não") -> #DIV/0! | AK4: 6 | AL4: =+IF(Input!$F$49<AI4,"Sim","Não") -> #DIV/0! | AN4: =CONCATENATE("De ",AO3," até ",AO4," mm2") -> De 2,5 até 4 mm2 | AO4: 4 | AP4: =+IF(AR4="Sim",IF(AR3="Não","Sim","Não"),"Não") -> Não | AQ4: 4 | AR4: =+IF(Input!$I$48<AO4,"Sim","Não") -> Sim
A5: Condomínio | C5: A3a - Tensão de fornecimento de 30 kV a 44 kV | E5: Industrial | H5: 220/380 | J5: UTE - Usina Termelétrica | N5: UTE - Biomassa - Biogás - RU | Z5: 3 | AD5: BelEnergy | AF5: SOLIS | AH5: =CONCATENATE("De ",AI4," até ",AI5," mm2") -> De 6 até 10 mm2 | AI5: 10 | AJ5: =+IF(AL5="Sim",IF(AL4="Não","Sim","Não"),"Não") -> #DIV/0! | AK5: 10 | AL5: =+IF(Input!$F$49<AI5,"Sim","Não") -> #DIV/0! | AN5: =CONCATENATE("De ",AO4," até ",AO5," mm2") -> De 4 até 6 mm2 | AO5: 6 | AP5: =+IF(AR5="Sim",IF(AR4="Não","Sim","Não"),"Não") -> Não | AQ5: 6 | AR5: =+IF(Input!$I$48<AO5,"Sim","Não") -> Sim
C6: A4 - Tensão de fornecimento de 2,3 kV a 25 kV | E6: Poder Público | N6: UTE - Biomassa - Biogás - RAGR | Z6: 4 | AD6: Risen | AF6: PHB | AH6: =CONCATENATE("De ",AI5," até ",AI6," mm2") -> De 10 até 15 mm2 | AI6: 15 | AJ6: =+IF(AL6="Sim",IF(AL5="Não","Sim","Não"),"Não") -> #DIV/0! | AK6: 15 | AL6: =+IF(Input!$F$49<AI6,"Sim","Não") -> #DIV/0! | AN6: =CONCATENATE("De ",AO5," até ",AO6," mm2") -> De 6 até 10 mm2 | AO6: 10 | AP6: =+IF(AR6="Sim",IF(AR5="Não","Sim","Não"),"Não") -> Não | AQ6: 10 | AR6: =+IF(Input!$I$48<AO6,"Sim","Não") -> Sim
C7: AS - Tensão de fornecimento inferior a 2,3 kV, a partir de sistema subterrâneo de distribuição | E7: Serviço Público | N7: UTE - Biomassa - Capim Elefante | Z7: 5 | AD7: Jinko | AF7: SUNGROW | AH7: =CONCATENATE("De ",AI6," até ",AI7," mm2") -> De 15 até 25 mm2 | AI7: 25 | AJ7: =+IF(AL7="Sim",IF(AL6="Não","Sim","Não"),"Não") -> #DIV/0! | AK7: 25 | AL7: =+IF(Input!$F$49<AI7,"Sim","Não") -> #DIV/0! | AN7: =CONCATENATE("De ",AO6," até ",AO7," mm2") -> De 10 até 15 mm2 | AO7: 15 | AP7: =+IF(AR7="Sim",IF(AR6="Não","Sim","Não"),"Não") -> Não | AQ7: 15 | AR7: =+IF(Input!$I$48<AO7,"Sim","Não") -> Sim
C8: B1 - Residencial | N8: UTE - Biomassa - Carvão - RU | V8: Estrutura | Z8: 6 | AD8: Longi | AF8: GROWATT | AH8: =CONCATENATE("De ",AI7," até ",AI8," mm2") -> De 25 até 35 mm2 | AI8: 35 | AJ8: =+IF(AL8="Sim",IF(AL7="Não","Sim","Não"),"Não") -> #DIV/0! | AK8: 35 | AL8: =+IF(Input!$F$49<AI8,"Sim","Não") -> #DIV/0! | AN8: =CONCATENATE("De ",AO7," até ",AO8," mm2") -> De 15 até 25 mm2 | AO8: 25 | AP8: =+IF(AR8="Sim",IF(AR7="Não","Sim","Não"),"Não") -> Não | AQ8: 25 | AR8: =+IF(Input!$I$48<AO8,"Sim","Não") -> Sim
C9: B2 - Rural | H9: Cobre | N9: UTE - Biomassa - Carvão Vegetal | V9: Fibrocimento | AD9: Trina | AF9: Deye | AH9: =CONCATENATE("De ",AI8," até ",AI9," mm2") -> De 35 até 50 mm2 | AI9: 50 | AJ9: =+IF(AL9="Sim",IF(AL8="Não","Sim","Não"),"Não") -> #DIV/0! | AK9: 50 | AL9: =+IF(Input!$F$49>AI8,"Sim","Não") -> #DIV/0! | AN9: =CONCATENATE("De ",AO8," até ",AO9," mm2") -> De 25 até 35 mm2 | AO9: 35 | AP9: =+IF(AR9="Sim",IF(AR8="Não","Sim","Não"),"Não") -> Não | AQ9: 35 | AR9: Sim
A10: TIPO DE LIGAÇÃO* | C10: B3 - Demais classes | H10: Alumínio | N10: UTE - Biomassa - Casca de Arroz | R10: Rua | V10: Cerâmico | AD10: Amerisolar | AF10: Goodwe
A11: Alta tensão | C11: B4 - Iluminação Pública | N11: UTE - Biomassa - Etanol | R11: Av. | V11: Aluzinco | AD11: Beyondsun
A12: Alta tensão subterrânea | N12: UTE - Gás de Alto Forno - Biomassa | R12: Estrada | V12: Laje | AD12: DAH | AI12: =Input!F49 -> #DIV/0! | AK12: =VLOOKUP("Sim",$AJ$3:$AK$10,2,FALSE) -> #N/A | AO12: =Input!I48 -> 2.1845455 | AQ12: =VLOOKUP("Sim",$AP$3:$AQ$10,2,FALSE) -> 2.5
A13: Comum trifásica BT | N13: UTE - Biomassa - Lenha | AD13: TSUN
A14: Trifásica Subterrânea BT | N14: UTE - Biomassa - Licor Negro | V14: Orientação | AD14: Taoistic
N15: UTE - Biomassa - Óleo Vegetal | V15: Norte | AD15: Honor
V16: Norte / Leste | AD16: Sunova
V17: Norte / Oeste | AD17: Topsola
N18: UTE - Biomassa - Resíduos Vegetais | V18: Nordeste | AD18: Sunergy
N19: UTE - Fóssil - Calor de Processo - CM | V19: Noroeste | AD19: OSDA
A20: Sim | N20: UTE - Fóssil - Calor de Processo - GN | V20: Leste | AD20: DMEGC
V21: Oeste | AD21: Pulling Energy
A22: Não | C22: ANEXO J - DIMENSIONAMENTO DE ENTRADA DE SERVIÇO - RIC BT | J22: CAIXA | K22: TAMANHO | L22: MODELO | N22: UTE - Fóssil - Calor de Processo - OF | R22: solarweb | S22: SOLAR.WEB | T22: WWW.SOLARWEB.COM | V22: Leste / Oeste
C23: A1 (Conforme anexo J - RIC BT) | D23: 10 | E23: 50 | F23: 10 | G23: 10 | H23: D-10 | J23: Alumínio | K23: 1 | L23: CI | N23: UTE - Fóssil - Carvão Mineral | R23: sicessolar | S23: SICES SOLAR | T23: WWW.MONITORAMENTO.SICESSOLAR.COM.BR
C24: B1 (Conforme anexo J - RIC BT) | D24: 15 | E24: 50 | F24: 10 | G24: 10 | H24: T-10 | J24: Chapa de Aço | K24: 1A | L24: CE | N24: UTE - Fóssil - Gás de Alto Forno - CM | R24: CSI cloud | S24: CSI CLOUD | T24: WWW.WEBMONITOR.CANADIANSOLAR.COM | V24: Vendedor responsável
C25: C1 (Conforme anexo J - RIC BT) | D25: 10 | E25: 30 | F25: 6 | G25: 10 | H25: Q-10 | J25: Madeira | K25: 2 | L25: CLI | N25: UTE - Fóssil - Gás de Alto Forno - PE | R25: ABB aurora | S25: ENERGY VIEWER | T25: WWW.AURORAVISION.NET | V25: Artur Melo
A26: CPF | C26: C2 (Conforme anexo J - RIC BT) | D26: 15 | E26: 40 | F26: 10 | G26: 10 | H26: Q-10 | J26: Policarbonato | K26: 2A | L26: CLE | N26: UTE - Fóssil - Gás de Refinaria | R26: Renovigi String | S26: SOLARMAN | T26: WWW.SOLARMANPV.COM | V26: Tiago Flores
A27: CNPJ | C27: C3 (Conforme anexo J - RIC BT) | D27: 19 | E27: 50 | F27: 10 | G27: 10 | H27: Q-10 | J27: Polietileno | K27: 3 | L27: CPO | N27: UTE - Fóssil - Gás Natural | R27: Renovigi Micro | S27: RENOVIEW | T27: WWW.RENOVIGIPORTAL.COM | V27: Tobias Flores
C28: C4 (Conforme anexo J - RIC BT) | D28: 27 | E28: 70 | F28: 25 | G28: 10 | H28: Q-16 | J28: Resina de Poliéster | K28: 4 | L28: CPOL | N28: UTE - Fóssil - Óleo Díesel | R28: phb solar | S28: PHB MONITOR | T28: WWW.PHBSOLAR.COM.BR | V28: Jackson Schmitz
C29: C5 (Conforme anexo J - RIC BT) | D29: 38 | E29: 100 | F29: 35 | G29: 16 | H29: Q-25 | J29: Fibra | K29: 5 | L29: CPOM | N29: UTE - Fóssil - Outros Energéticos de Petróleo
A30: Microgeração | C30: C6 (Conforme anexo J - RIC BT) | D30: 47 | E30: 125 | F30: 50 | G30: 25 | H30: Q-35 | J30: Padrão Multi 100 | K30: 6 | N30: UTE - Fóssil - Turfa | V30: Distribuidor
A31: Minigeração | C31: C7 (Conforme anexo J - RIC BT) | D31: 57 | E31: 150 | F31: 70 | G31: Analisar Subterrâneo | H31: Analisar Subterrâneo | J31: Padrão Multi 200 | K31: 7 | N31: UTE - Fóssil - Xisto | V31: Mazer
C32: C8 (Conforme anexo J - RIC BT) | D32: 66 | E32: 175 | F32: 95 | G32: Analisar Subterrâneo | H32: Analisar Subterrâneo | J32: Policarbonato e poliéster | K32: 8 | V32: Ten Brasil
C33: C9 (Conforme anexo J - RIC BT) | D33: 75 | E33: 200 | F33: 120 | G33: Analisar Subterrâneo | H33: Analisar Subterrâneo | K33: 9 | V33: BelEnergy
C34: TENSÃO 220V | D34: -- | E34: -- | F34: -- | G34: -- | H34: -- | K34: 10
C35: A2 (Conforme anexo J - RIC BT) | D35: 15 | E35: 40 | F35: 6 | G35: 10 | H35: D-10 | K35: 11
C36: B2 (Conforme anexo J - RIC BT) | D36: 25 | E36: 50 | F36: 10 | G36: 10 | H36: T-10 | K36: Monofásica
C37: C13 (Conforme anexo J - RIC BT) | D37: 19 | E37: 30 | F37: 6 | G37: 10 | H37: Q-10 | K37: Polifásica
C38: C14 (Conforme anexo J - RIC BT) | D38: 26 | E38: 40 | F38: 10 | G38: 10 | H38: Q-10
C39: C15 (Conforme anexo J - RIC BT) | D39: 32 | E39: 50 | F39: 10 | G39: 10 | H39: Q-10
C40: C16 (Conforme anexo J - RIC BT) | D40: 46 | E40: 70 | F40: 25 | G40: 10 | H40: Q-16
...

Sheet BD Inv
A1: 1 | B1: 2 | C1: 3 | D1: 4 | E1: 5 | F1: 6 | G1: 7 | H1: 8 | I1: 9 | J1: 10 | K1: 11 | L1: 12 | M1: 13 | N1: 14 | O1: 15 | P1: 16 | Q1: 17
C2: Máxima potência CC (W) | D2: Tensão de entrada máx. | E2: Faixa de Tensão de Entrada Mínima | F2: Faixa de Tensão de Entrada Máxima | G2: Faixa de operação SPMP – MPPT (V) | H2: Corrente CC máxima (A) | I2: Número de strings em paralelo | J2: Potência CA nominal (W) | K2: Máxima Potência CA | L2: Corrente CA máxima (A) | M2: Saída nominal CA 60 Hz; | N2: Eficiência | O2: Grau de Proteção | P2: Registro Inmetro | Q2: Monitoramento | R2: N° de MPPTs
A3: Modelo | B3: Fornecedor
A4: S6-GR1P3K-M | B4: SOLIS | C4: 4500 | D4: 600 | E4: 80 | F4: 520 | G4: 80 ~ 500 | H4: 11 | I4: 2 | J4: 3000 | K4: 3300 | L4: 15.7 | M4: 160 - 285 V | O4: IP65
A5: S6-GR1P4K | B5: SOLIS | C5: 6800 | D5: 600 | E5: 80 | F5: 520 | G5: 90 ~ 520 | H5: 14 | I5: 1 | J5: 4000 | K5: 4400 | L5: 21 | M5: 160 - 285 V | O5: IP65
A6: S6-GR1P5K | B6: SOLIS | C6: 8500 | D6: 600 | E6: 120 | F6: 600 | G6: 90 ~ 520 | H6: 14 | I6: 1 | J6: 5000 | K6: 5000 | L6: 25 | M6: 160 - 285 V | O6: IP65
A7: MINI 3000 4G | B7: SOLIS | C7: 4500 | D7: 600 | E7: 90 | F7: 520 | G7: 80 ~ 500 | H7: 11 | I7: 2 | J7: 3000 | K7: 3300 | L7: 15.7 | M7: 160 - 285 V | O7: IP65
A8: 1P4K-4G | B8: SOLIS | C8: 6000 | D8: 600 | E8: 120 | F8: 520 | G8: 80 ~ 500 | H8: 11 | I8: 2 | J8: 4000 | K8: 4400 | L8: 21 | M8: 160 - 285 V | O8: IP65
A9: 1P5K-4G | B9: SOLIS | C9: 7500 | D9: 600 | E9: 120 | F9: 520 | G9: 90 ~ 520 | H9: 11 | I9: 2 | J9: 5000 | K9: 5000 | L9: 25 | M9: 160 - 285 V | O9: IP65
A10: 1P6K-4G | B10: SOLIS | C10: 9000 | D10: 600 | E10: 120 | F10: 520 | G10: 90 ~ 520 | H10: 11 | I10: 2 | J10: 6000 | K10: 6000 | L10: 27.3 | M10: 160 - 285 V | O10: IP65
A11: 1P7K-5G | B11: SOLIS | C11: 10500 | D11: 600 | E11: 120 | F11: 520 | G11: 90 ~ 520 | H11: 11 | I11: 3 | J11: 7000 | K11: 7700 | L11: 35 | M11: 160 - 285 V | O11: IP65
A12: 1P7.7K-5G | B12: SOLIS | C12: 11550 | D12: 600 | E12: 120 | F12: 520 | G12: 90 ~ 520 | H12: 12.5 | I12: 3 | J12: 7700 | K12: 7700 | L12: 35 | M12: 160 - 285 V | O12: IP65
A13: S5-GR1P7K | B13: SOLIS | C13: 11900 | D13: 600 | E13: 120 | F13: 500 | G13: 100 ~ 500 | H13: 14 | I13: 3 | J13: 7000 | K13: 7700 | L13: 33.7 | M13: 160 - 285 V | O13: IP65
A14: S5-GR1P8K | B14: SOLIS | C14: 13600 | D14: 600 | E14: 120 | F14: 500 | G14: 100 ~ 500 | H14: 14 | I14: 3 | J14: 8000 | K14: 8800 | L14: 33.6 | M14: 160 - 285 V | O14: IP65
A15: S5-GR1P9K | B15: SOLIS | C15: 15300 | D15: 600 | E15: 120 | F15: 500 | G15: 100 ~ 500 | H15: 14 | I15: 3 | J15: 9000 | K15: 9900 | L15: 41.3 | M15: 160 - 285 V | O15: IP65
... A17: S5-GR1P15K | B17: SOLIS | C17: 22500 | D17: 600 | E17: 180 | F17: 600 | G17: 180 ~ 1000 | H17: 32 | I17: 4 | J17: 15000 | K17: 16500 | L17: 23.8 | M17: 160 - 285 V | O17: IP65
A18: SOLIS-3P10K-4G | B18: SOLIS | C18: =10000*1.5 -> 15000 | D18: 600 | E18: 180 | F18: 600 | G18: 160 ~ 850 | H18: 11 | I18: 3 | J18: 10000 | K18: 11000 | L18: 15.9 | M18: 160 - 285 V | O18: IP65
A19: SOLIS-3P12K-4G | B19: SOLIS | C19: =12000*1.5 -> 18000 | D19: 600 | E19: 180 | F19: 600 | G19: 160 ~ 850 | H19: 22 | I19: 4 | J19: 12000 | K19: 13200 | L19: 19.1 | M19: 160 - 285 V | O19: IP65
A20: SOLIS-3P15K-4G | B20: SOLIS | C20: =15000*1.5 -> 22500 | D20: 600 | E20: 180 | F20: 600 | G20: 160 ~ 850 | H20: 22 | I20: 4 | J20: 15000 | K20: 16500 | L20: 23.8 | M20: 160 - 285 V | O20: IP65
A21: SOLIS-3P17K-4G | B21: SOLIS | C21: =17000*1.5 -> 25500 | D21: 600 | E21: 180 | F21: 600 | G21: 160 ~ 850 | H21: 22 | I21: 4 | J21: 17000 | K21: 18700 | L21: 27 | M21: 160 - 285 V | O21: IP65
A22: SOLIS-3P20K-4G | B22: SOLIS | C22: =20000*1.5 -> 30000 | D22: 600 | E22: 180 | F22: 600 | G22: 160 ~ 850 | H22: 22 | I22: 4 | J22: 20000 | K22: 22000 | L22: 31.8 | M22: 160 - 285 V | O22: IP65
A23: Solis-25K-5G | B23: SOLIS | C23: 37500 | D23: 600 | E23: 180 | F23: 600 | G23: 200 ~ 1000 | H23: 26 | I23: 3 | J23: 25000 | K23: 27500 | L23: 41.8 | M23: 160 - 285 V | O23: IP65
A24: Solis-40K-5G | B24: SOLIS | C24: 60000 | D24: 600 | E24: 180 | F24: 600 | G24: 200 ~ 1000 | H24: 26 | I24: 2 | J24: 40000 | K24: 44000 | L24: 66.9 | M24: 160 - 285 V | O24: IP65
A25: Solis-50K | B25: SOLIS | C25: 75000 | D25: 600 | E25: 200 | F25: 600 | G25: 200 ~ 1000 | H25: 28.5 | I25: 4 | J25: 50000 | K25: 55000 | L25: 83.3 | M25: 160 - 285 V | O25: IP65
A26: Solis-75K-5G | B26: SOLIS | C26: 126000 | D26: 600 | E26: 195 | F26: 600 | G26: 180 ~ 1000 | H26: 26 | I26: 2 | J26: 75000 | K26: 75000 | L26: 114 | M26: 160 - 285 V | O26: IP65
A27: GW5000T-NS | B27: GOODWE | C27: 6500 | D27: 600 | E27: 80 | F27: 600 | G27: 80 ~ 550 | H27: 11 | I27: 1 | J27: 6000 | K27: 6000 | L27: 27.3 | M27: 220 - 230 V | O27: IP65 | R27: 2
A28: 2000G3-US-220 | B28: DEYE | C28: 2000 | D28: 60 | E28: 20 | F28: 55 | G28: 20 ~ 55 | H28: 13 | I28: 1 | J28: 2000 | K28: 2000 | L28: 9.1 | M28: 176-242 V | O28: IP65
A29: S5-GC37.5K | B29: SOLIS | C29: 63800 | D29: 1100 | E29: 200 | F29: 1000 | G29: 200 ~ 1000 | H29: 32 | I29: 4 | J29: 37500 | K29: 37500 | L29: 57 | M29: 230-400 V | O29: IP66 | R29: 4
A30: S6-GR1P3K-M | B30: SOLIS
A31: SG3.0RS-L | B31: SUNGROW
A32: GW6K-DNS-G40

Sheet BD Mod
B1: 1 | C1: 2 | D1: 3 | E1: 4 | F1: 5 | G1: 6 | H1: 7 | I1: 8 | J1: 9 | K1: 10 | L1: 11 | M1: 12 | N1: 13 | O1: 14 | P1: 15 | Q1: 16 | R1: 17 | S1: 18
D2: Potência nominal máxima (W) | E2: Tensão máxima de voltagem – Vmp (V) | F2: Corrente máxima de corrente – Imp (A) | G2: Tensão de circuito aberto – Voc (V) | H2: Corrente de curto circuito Isc | I2: Eficiência | J2: Temperatura de Operação | K2: Tensão Máxima do Sistema | L2: Máxima de fusível em série (A) | M2: Tolerância de Energia | N2: Compr | O2: Largura | P2: área | Q2: Tipo | R2: N.Celulas
B3: TSM-DE18M | C3: Trina | D3: 510 | E3: 43.2 | F3: 11.81 | G3: 52.1 | H3: 12.42 | I3: 0.212 | J3: -40⁰C ~ +85⁰C | K3: 1000 V | L3: 30 | M3: 0 ~ + 5 W | N3: 2.187 | O3: 1.102 | P3: =+N3*O3 -> 2.410074 | Q3: Monocristalino | R3: 150
B4: CS3W-440MS | C4: Canadian | D4: 440 | E4: 40.7 | F4: 10.82 | G4: 40.7 | H4: 11,48, | I4: 0.1865 | J4: -40⁰C ~ +85⁰C | K4: 1000 V | L4: 30 | M4: 0 ~ + 5 W | N4: 2.108 | O4: 1.048 | P4: =+N4*O4 -> 2.209184 | Q4: Monocristalino | R4: 144
B5: CS3W-450MS | C5: Canadian | D5: 450 | E5: 41.1 | F5: 10.96 | G5: 49.1 | H5: 11.6 | I5: 0.204 | J5: -40⁰C ~ +85⁰C | K5: 1000 V | L5: 30 | M5: 0 ~ + 5 W | N5: 2.108 | O5: 1.048 | P5: =+N5*O5 -> 2.209184 | Q5: Monocristalino | R5: 144
B6: CS3W-455MS | C6: Canadian | D6: 455 | E6: 41.3 | F6: 11.02 | G6: 41.3 | H6: 11.66 | I6: 0.1941 | J6: -40⁰C ~ +85⁰C | K6: 1000 V | L6: 30 | M6: 0 ~ + 5 W | N6: 2.108 | O6: 1.048 | P6: =+N6*O6 -> 2.209184 | Q6: Monocristalino | R6: 144
B7: CS6W-545Ms | C7: Canadian | D7: 545 | E7: 41.5 | F7: 13.14 | G7: 49.4 | H7: 13.95 | I7: 0.213 | J7: -40⁰C ~ +85⁰C | K7: 1500 V | L7: 25 | M7: 0 ~ + 10 W | N7: 2.261 | O7: 1.134 | P7: =+N7*O7 -> 2.563974 | Q7: Monocristalino | R7: 144
B8: TSHM535-144HV | C8: Beyondsun | D8: 535 | E8: 37.2 | F8: 8.88 | G8: 45.6 | H8: 9.45 | I8: 0.1697 | J8: -40⁰C ~ +85⁰C | K8: 1000 V | L8: 15 | M8: 0 ~ + 5 W | N8: 2.2279 | O8: 1.134 | P8: =+N8*O8 -> 2.5264386 | Q8: Monocristalino | R8: 144
B9: MFVRE-MO-144-550W | C9: BelEnergy | D9: 550 | E9: 41.96 | F9: 13.11 | G9: 49.9 | H9: 14 | I9: 0.213 | J9: -40⁰C ~ +85⁰C | K9: 1500 V | L9: 25 | M9: 0 ~ + 5 W | N9: 2.279 | O9: 1.134 | P9: =+N9*O9 -> 2.584386 | Q9: Monocristalino | R9: 144
B10: MFVOS-MO-120-460W | C10: BelEnergy | D10: 460 | E10: 35.11 | F10: 13.11 | G10: 41.8 | H10: 13.93 | I10: 0.213 | J10: -40⁰C ~ +85⁰C | K10: 1500 V | L10: 25 | M10: 0 ~ + 5 W | N10: 1.903 | O10: 1.134 | P10: =+N10*O10 -> 2.158002 | Q10: Monocristalino | R10: 120
B11: MFREN-MO-144-455W | C11: BelEnergy | D11: 455 | E11: 41.73 | F11: 10.93 | G11: 49.5 | H11: 11.65 | I11: 0.209 | J11: -40⁰C ~ +85⁰C | K11: 1500 V | L11: 15 | M11: 0 ~ + 5 W | N11: 2.094 | O11: 1.039 | P11: =+N11*O11 -> 2.175666 | Q11: Monocristalino | R11: 144
B12: 450 MGK-36 | C12: BYD | D12: 450 | E12: 41.58 | F12: 10.84 | G12: 49.59 | H12: 11.64 | I12: 0.2067 | J12: -40⁰C ~ +85⁰C | K12: 1500 V | L12: 20 | M12: 0 ~ + 5 W | N12: 2.094 | O12: 1.038 | P12: =+N12*O12 -> 2.173572 | Q12: Monocristalino | R12: 144
B13: 530 MLK-36 | C13: BYD | D13: 530 | E13: 41.61 | F13: 12.74 | G13: 49.12 | H13: 13.45 | I13: 0.2071 | J13: -40⁰C ~ +85⁰C | K13: 1500 V | L13: 25 | M13: 0 ~ + 5 W | N13: 2.256 | O13: 1.133 | P13: =+N13*O13 -> 2.556048 | Q13: Monocristalino | R13: 144
B14: DHT-M60X10-460W | C14: DAH | D14: 460 | E14: 52.8 | F14: 8.71 | G14: 62.4 | H14: 9.31 | I14: 0.213 | J14: -40⁰C ~ +85⁰C | K14: 1500 V | L14: 20 | M14: 0 ~ + 5 W | N14: 1.903 | O14: 1.134 | P14: =+N14*O14 -> 2.158002 | Q14: Monocristalino | R14: 180 | U14: Maximum Reverse Current
B15: DHM-60X10-460W | C15: DAH | D15: 460 | E15: 35.5 | F15: 12.97 | G15: 42 | H15: 13.78 | I15: 0.2124 | J15: -40⁰C ~ +85⁰C | K15: 1500 V | L15: 25 | M15: 0 ~ + 5 W | N15: 1.91 | O15: 1.134 | P15: =+N15*O15 -> 2.16594 | Q15: Monocristalino | R15: 120
B16: DHM-72X10-550W | C16: DAH | D16: 550 | E16: 42.4 | F16: 12.97 | G16: 50.2 | H16: 13.78 | I16: 0.2128 | J16: -40⁰C ~ +85⁰C | K16: 1500 V | L16: 25 | M16: 0 ~ + 5 W | N16: 2.279 | O16: 1.134 | P16: =+N16*O16 -> 2.584386 | Q16: Monocristalino | R16: 144
B17: AE505HM6L-66 | C17: AE Solar | D17: 505 | E17: 39.27 | F17: 12.86 | G17: 46.93 | H17: 13.62 | I17: 0.213 | J17: -40⁰C ~ +85⁰C | K17: 1500 V | L17: 25 | M17: 0 ~ + 5 W | N17: 2.094 | O17: 1.134 | P17: =+N17*O17 -> 2.374596 | Q17: Monocristalino | R17: 132
B18: TS560S8B | C18: TSUN | D18: 560 | E18: 42.3 | F18: 13.25 | G18: 50.1 | H18: 13.98 | I18: 0.217 | J18: -40⁰C ~ +85⁰C | K18: 1500 V | L18: 25 | M18: 0 ~ + 5 W | N18: 2.261 | O18: 1.134 | P18: =+N18*O18 -> 2.563974 | Q18: Monocristalino | R18: 144
B19: TS-M10/144H | C19: Taoistic | D19: 550 | E19: 41.28 | F19: 13.32 | G19: 49.8 | H19: 14.01 | I19: 0.2129 | J19: -40⁰C ~ +85⁰C | K19: 1500 V | L19: 25 | M19: 0 ~ + 5 W | N19: 2.278 | O19: 1134 | P19: =+N19*O19 -> 2583.252 | Q19: Monocristalino | R19: 144
B20: LR5-72HPH-550M | C20: Longi | D20: 550 | E20: 41.95 | F20: 13.12 | G20: 49.8 | H20: 13.98 | I20: 0.213 | J20: -40⁰C ~ +85⁰C | K20: 1500 V | L20: 25 | M20: 0 ~ + 3 W | N20: 2.278 | O20: 1.134 | P20: =+N20*O20 -> 2.583252 | Q20: Monocristalino | R20: 144
B21: HY-M10/144 | C21: Honor | D21: 550 | E21: 41.28 | F21: 13.32 | G21: 49.8 | H21: 14.01 | I21: 0.214 | J21: -40⁰C ~ +85⁰C | K21: 1500 V | L21: 25 | M21: 0 ~ + 5 W | N21: 2.278 | O21: 1.134 | P21: =+N21*O21 -> 2.583252 | Q21: Monocristalino | R21: 144
B22: LR5-72HPH-560M | C22: Longi | D22: 560 | E22: 42.25 | F22: 13.26 | G22: 50.1 | H22: 14.1 | I22: 0.217 | J22: -40⁰C ~ +85⁰C | K22: 1500 V | L22: 25 | M22: 0 ~ + 3 W | N22: 2.278 | O22: 1.134 | P22: =+N22*O22 -> 2.583252 | Q22: Monocristalino | R22: 144
B23: S5-555-72MDH | C23: SUNOVA | D23: 555 | E23: 40.89 | F23: 13.58 | G23: 49.68 | H23: 14.13 | I23: 0.213 | J23: -40⁰C ~ +85⁰C | K23: 1500 V | L23: 25 | M23: 0 ~ + 5 W | N23: 2.278 | O23: 1.134 | P23: =+N23*O23 -> 2.583252 | Q23: Monocristalino | R23: 144
B24: TPS560 | C24: TOPSOLA | D24: 560 | E24: 42.25 | F24: 13.26 | G24: 50.1 | H24: 14.1 | I24: 0.217 | J24: -40⁰C ~ +85⁰C | K24: 1500 V | L24: 25 | M24: 0 ~ + 3 W | N24: 2.278 | O24: 1.134 | P24: =+N24*O24 -> 2.583252 | Q24: Monocristalino | R24: 144
B25: SUN 72M-H8N 570W | C25: Sunergy | D25: 570 | E25: 41.92 | F25: 13.48 | G25: 50.6 | H25: 14.23 | I25: 0.2187 | J25: -40⁰C ~ +85⁰C | K25: 1500 V | L25: 25 | M25: 0 ~ + 3 W | N25: 2.278 | O25: 1.134 | P25: =+N25*O25 -> 2.583252 | Q25: Monocristalino | R25: 144
B26: S5-580-72MDH(T) | C26: SUNOVA | D26: 580 | E26: 44.48 | F26: 13.04 | G26: 51.9 | H26: 13.61 | I26: 0.22 | J26: -40⁰C ~ +85⁰C | K26: 1500 V | L26: 25 | M26: 0 ~ + 3 W | N26: 2.278 | O26: 1.134 | P26: =+N26*O26 -> 2.583252 | Q26: Monocristalino | R26: 144
B27: ODA585-36V-MHD | C27: OSDA | D27: 585 | N27: 2.278 | O27: 1.134 | P27: =+N27*O27 -> 2.583252 | Q27: Monocristalino | R27: 144
B28: DM585M10T -B72HSW | C28: DMEGC | D28: 585 | N28: 2.278 | O28: 1.134 | P28: =+N28*O28 -> 2.583252 | Q28: Monocristalino | R28: 144
B29: PU585WNM101 | C29: Pulling Energy | D29: 585 | N29: 2.3334 | O29: 1.134 | P29: =+N29*O29 -> 2.6460756 | Q29: Monocristalino | R29: 144
